Traceback (most recent call last):
  File "/home/nenad/Documents/Luigi/Luigi/bin/luigid", line 11, in <module>
    load_entry_point('luigi==3.0.0', 'console_scripts', 'luigid')()
  File "/home/nenad/Documents/Luigi/Luigi/lib/python3.8/site-packages/luigi/cmdline.py", line 33, in luigid
    luigi.process.daemonize(luigi.server.run, api_port=opts.port,
  File "/home/nenad/Documents/Luigi/Luigi/lib/python3.8/site-packages/luigi/process.py", line 126, in daemonize
    cmd(api_port=api_port, address=address, unix_socket=unix_socket)
  File "/home/nenad/Documents/Luigi/Luigi/lib/python3.8/site-packages/luigi/server.py", line 337, in run
    _init_api(
  File "/home/nenad/Documents/Luigi/Luigi/lib/python3.8/site-packages/luigi/server.py", line 319, in _init_api
    api_sockets = tornado.netutil.bind_sockets(api_port, address=address)
  File "/home/nenad/Documents/Luigi/Luigi/lib/python3.8/site-packages/tornado/netutil.py", line 168, in bind_sockets
    sock.bind(sockaddr)
OSError: [Errno 98] Address already in use
Traceback (most recent call last):
  File "/home/nenad/Documents/Luigi/Luigi/bin/luigid", line 11, in <module>
    load_entry_point('luigi==3.0.0', 'console_scripts', 'luigid')()
  File "/home/nenad/Documents/Luigi/Luigi/lib/python3.8/site-packages/luigi/cmdline.py", line 33, in luigid
    luigi.process.daemonize(luigi.server.run, api_port=opts.port,
  File "/home/nenad/Documents/Luigi/Luigi/lib/python3.8/site-packages/luigi/process.py", line 126, in daemonize
    cmd(api_port=api_port, address=address, unix_socket=unix_socket)
  File "/home/nenad/Documents/Luigi/Luigi/lib/python3.8/site-packages/luigi/server.py", line 337, in run
    _init_api(
  File "/home/nenad/Documents/Luigi/Luigi/lib/python3.8/site-packages/luigi/server.py", line 319, in _init_api
    api_sockets = tornado.netutil.bind_sockets(api_port, address=address)
  File "/home/nenad/Documents/Luigi/Luigi/lib/python3.8/site-packages/tornado/netutil.py", line 168, in bind_sockets
    sock.bind(sockaddr)
OSError: [Errno 98] Address already in use
Traceback (most recent call last):
  File "/home/nenad/Documents/Luigi/Luigi/bin/luigid", line 11, in <module>
    load_entry_point('luigi==3.0.0', 'console_scripts', 'luigid')()
  File "/home/nenad/Documents/Luigi/Luigi/lib/python3.8/site-packages/luigi/cmdline.py", line 33, in luigid
    luigi.process.daemonize(luigi.server.run, api_port=opts.port,
  File "/home/nenad/Documents/Luigi/Luigi/lib/python3.8/site-packages/luigi/process.py", line 126, in daemonize
    cmd(api_port=api_port, address=address, unix_socket=unix_socket)
  File "/home/nenad/Documents/Luigi/Luigi/lib/python3.8/site-packages/luigi/server.py", line 337, in run
    _init_api(
  File "/home/nenad/Documents/Luigi/Luigi/lib/python3.8/site-packages/luigi/server.py", line 319, in _init_api
    api_sockets = tornado.netutil.bind_sockets(api_port, address=address)
  File "/home/nenad/Documents/Luigi/Luigi/lib/python3.8/site-packages/tornado/netutil.py", line 168, in bind_sockets
    sock.bind(sockaddr)
OSError: [Errno 98] Address already in use
Traceback (most recent call last):
  File "/home/nenad/Documents/Luigi/Luigi/bin/luigid", line 11, in <module>
    load_entry_point('luigi==3.0.0', 'console_scripts', 'luigid')()
  File "/home/nenad/Documents/Luigi/Luigi/lib/python3.8/site-packages/luigi/cmdline.py", line 33, in luigid
    luigi.process.daemonize(luigi.server.run, api_port=opts.port,
  File "/home/nenad/Documents/Luigi/Luigi/lib/python3.8/site-packages/luigi/process.py", line 126, in daemonize
    cmd(api_port=api_port, address=address, unix_socket=unix_socket)
  File "/home/nenad/Documents/Luigi/Luigi/lib/python3.8/site-packages/luigi/server.py", line 337, in run
    _init_api(
  File "/home/nenad/Documents/Luigi/Luigi/lib/python3.8/site-packages/luigi/server.py", line 319, in _init_api
    api_sockets = tornado.netutil.bind_sockets(api_port, address=address)
  File "/home/nenad/Documents/Luigi/Luigi/lib/python3.8/site-packages/tornado/netutil.py", line 168, in bind_sockets
    sock.bind(sockaddr)
OSError: [Errno 98] Address already in use
